<?xml version="1.0"?>
<robot name="robot1">

  <link name="chassis">
    <inertial>
     <origin xyz="0 0 0.0" rpy="0 0 0"/>
     <mass value="1"/>
     <inertia ixx="0.0075"  ixy="0"  ixz="0" iyy="0.02" iyz="0" izz="0.02" />
   </inertial>
    <visual>
      <geometry>
        <box size="0.5 0.3 0.01"/>
      </geometry>
      <origin xyz="0.0 0.0 0.05" />
    </visual>
    <collision>
     <geometry>
        <box size="0.5 0.3 0.01"/>
      </geometry>
      <origin xyz="0.0 0.0 0.05" />
   </collision>
  </link>

  <link name="left_wheel">
    <inertial>
     <origin xyz="0 0 0" rpy="0 0 0"/>
     <mass value="1"/>
     <inertia ixx="0.0007"  ixy="0"  ixz="0" iyy="0.00125" iyz="0" izz="0.0007" />
   </inertial>
    <visual>
      <geometry>
        <cylinder length="0.03" radius="0.05"/>
      </geometry>
      <origin xyz="0.0 0 0.0" rpy="0 1.57 1.57"/>
      <material name="Cyan">
       <color rgba="0 0.0 1.0 1.0"/>
     </material>
    </visual>
    <collision>
     <geometry>
        <cylinder length="0.03" radius="0.05"/>
      </geometry>
      <origin xyz="0.0 0 0.0" rpy="0 1.57 1.57"/>
   </collision>
  </link>

  <gazebo reference="left_wheel">
    <mu1>1.2</mu1>
    <mu2>1.2</mu2>
    <kp>500000.0</kp>
    <kd>10.0</kd>
    <minDepth>0.001</minDepth>
    <maxVel>0.1</maxVel>
    <material>Gazebo/FlatBlack</material>
  </gazebo>

  <joint name="chassis_to_left_wheel" type="continuous">
    <parent link="chassis"/>
    <child link="left_wheel"/>
    <axis xyz="0 1 0"/>
    <origin xyz="0.17 0.18 0.05" rpy="0 0.0 0.0"/>
  </joint>


   <link name="right_wheel">
    <inertial>
     <origin xyz="0 0 0" rpy="0 0 0"/>
     <mass value="1"/>
     <inertia ixx="0.0007"  ixy="0"  ixz="0" iyy="0.00125" iyz="0" izz="0.0007" />
   </inertial>
    <visual>
      <geometry>
        <cylinder length="0.03" radius="0.05"/>
      </geometry>
      <origin xyz="0.0 0 0.0" rpy="0 1.57 1.57"/>
      <material name="Cyan">
       <color rgba="0 0.0 1.0 1.0"/>
     </material>
    </visual>
    <collision>
     <geometry>
        <cylinder length="0.03" radius="0.05"/>
      </geometry>
      <origin xyz="0.0 0 0.0" rpy="0 1.57 1.57"/>
   </collision>
  </link>

  <gazebo reference="right_wheel">
    <mu1>1.2</mu1>
    <mu2>1.2</mu2>
    <kp>500000.0</kp>
    <kd>10.0</kd>
    <minDepth>0.001</minDepth>
    <maxVel>0.1</maxVel>
    <material>Gazebo/FlatBlack</material>
  </gazebo>

  <joint name="chassis_to_right_wheel" type="continuous">
    <parent link="chassis"/>
    <child link="right_wheel"/>
    <axis xyz="0 1 0"/>
    <origin xyz="0.17 -0.18 0.05" rpy="0 0.0 0.0"/>
  </joint>

  <link name="roue_folle">
    <inertial>
     <origin xyz="0 0 0.0" rpy="0 0 0"/>
     <mass value="1.0"/>
     <inertia ixx="0.00025"  ixy="0"  ixz="0" iyy="0.00025" iyz="0" izz="0.00025" />
   </inertial>
    <visual>
      <geometry>
        <sphere radius="0.025"/>
      </geometry>
      <origin xyz="0 0 0" rpy="0 0 0"/>
    </visual>
    <collision>
     <geometry>
        <sphere radius="0.025"/>
      </geometry>
      <origin xyz="0 0 0" rpy="0 0 0"/>
   </collision>
  </link>

  <gazebo reference="roue_folle">
    <mu1>0.1</mu1>
    <mu2>0.1</mu2>
    <kp>500000.0</kp>
    <kd>10.0</kd>
    <minDepth>0.001</minDepth>
    <maxVel>0.1</maxVel>
    <material>Gazebo/FlatBlack</material>
  </gazebo>

  <joint name="chassis_to_folle" type="fixed">
    <parent link="chassis"/>
    <child link="roue_folle"/>
    <origin xyz="-0.167 0 0.03" rpy="0 0 0"/>
  </joint>



</robot>