<?xml version="1.0"?>
<robot name="robot1">

  <link name="chassis">
    <inertial>
     <origin xyz="0 0 0.0" rpy="0 0 0"/>
     <mass value="1"/>
     <inertia ixx="0.02"  ixy="0"  ixz="0" iyy="0.028" iyz="0" izz="0.0076" />
   </inertial>
    <visual>
      <geometry>
        <box size="0.5 0.3 0.04"/>
      </geometry>
      <origin xyz="0.0 0.0 0.05" />
    </visual>
    <collision>
     <geometry>
        <box size="0.5 0.3 0.04"/>
      </geometry>
      <origin xyz="0.0 0.0 0.05" />
   </collision>
  </link>

  <link name="left_wheel">
    <inertial>
     <origin xyz="0 0 0" rpy="0 0 0"/>
     <mass value="1"/>
     <inertia ixx="0.0007"  ixy="0"  ixz="0" iyy="0.00125" iyz="0" izz="0.0007" />
   </inertial>
    <visual>
      <geometry>
        <cylinder length="0.03" radius="0.05"/>
      </geometry>
      <origin xyz="0.0 0 0.0" rpy="0 1.57 1.57"/>
      <material name="Cyan">
       <color rgba="0 0.0 1.0 1.0"/>
     </material>
    </visual>
    <collision>
     <geometry>
        <cylinder length="0.03" radius="0.05"/>
      </geometry>
      <origin xyz="0.0 0 0.0" rpy="0 1.57 1.57"/>
   </collision>
  </link>

  <gazebo reference="left_wheel">
    <mu1>1.2</mu1>
    <mu2>1.2</mu2>
    <kp>500000.0</kp>
    <kd>10.0</kd>
    <minDepth>0.001</minDepth>
    <maxVel>0.1</maxVel>
    <material>Gazebo/FlatBlack</material>
  </gazebo>

  <joint name="chassis_to_left_wheel" type="continuous">
    <parent link="chassis"/>
    <child link="left_wheel"/>
    <axis xyz="0 1 0"/>
    <origin xyz="0.17 0.18 0.05" rpy="0 0.0 0.0"/>
  </joint>


   <link name="right_wheel">
    <inertial>
     <origin xyz="0 0 0" rpy="0 0 0"/>
     <mass value="1"/>
     <inertia ixx="0.0007"  ixy="0"  ixz="0" iyy="0.00125" iyz="0" izz="0.0007" />
   </inertial>
    <visual>
      <geometry>
        <cylinder length="0.03" radius="0.05"/>
      </geometry>
      <origin xyz="0.0 0 0.0" rpy="0 1.57 1.57"/>
      <material name="Cyan">
       <color rgba="0 0.0 1.0 1.0"/>
     </material>
    </visual>
    <collision>
     <geometry>
        <cylinder length="0.03" radius="0.05"/>
      </geometry>
      <origin xyz="0.0 0 0.0" rpy="0 1.57 1.57"/>
   </collision>
  </link>

  <gazebo reference="right_wheel">
    <mu1>1.2</mu1>
    <mu2>1.2</mu2>
    <kp>500000.0</kp>
    <kd>10.0</kd>
    <minDepth>0.001</minDepth>
    <maxVel>0.1</maxVel>
    <material>Gazebo/FlatBlack</material>
  </gazebo>

  <joint name="chassis_to_right_wheel" type="continuous">
    <parent link="chassis"/>
    <child link="right_wheel"/>
    <axis xyz="0 1 0"/>
    <origin xyz="0.17 -0.18 0.05" rpy="0 0.0 0.0"/>
  </joint>

  <link name="roue_folle">
    <inertial>
     <origin xyz="0 0 0.0" rpy="0 0 0"/>
     <mass value="1.0"/>
     <inertia ixx="0.00025"  ixy="0"  ixz="0" iyy="0.00025" iyz="0" izz="0.00025" />
   </inertial>
    <visual>
      <geometry>
        <sphere radius="0.025"/>
      </geometry>
      <origin xyz="0 0 0" rpy="0 0 0"/>
    </visual>
    <collision>
     <geometry>
        <sphere radius="0.025"/>
      </geometry>
      <origin xyz="0 0 0" rpy="0 0 0"/>
   </collision>
  </link>

  <gazebo reference="roue_folle">
    <mu1>0.1</mu1>
    <mu2>0.1</mu2>
    <kp>500000.0</kp>
    <kd>10.0</kd>
    <minDepth>0.001</minDepth>
    <maxVel>0.1</maxVel>
    <material>Gazebo/FlatBlack</material>
  </gazebo>

  <joint name="chassis_to_folle" type="fixed">
    <parent link="chassis"/>
    <child link="roue_folle"/>
    <origin xyz="-0.167 0 0.03" rpy="0 0 0"/>
  </joint>

  <link name="left_pince">
    <inertial>
     <origin xyz="0 0 0.0" rpy="0 0 0"/>
     <mass value="1"/>
     <inertia ixx="0.0039"  ixy="0"  ixz="0" iyy="0.0034" iyz="0" izz="0.00057" />
   </inertial>
    <visual>
      <geometry>
        <box size="0.4 0.03 0.08"/>
      </geometry>
      <origin xyz="0.0 0.0 0.05" />
    </visual>
    <collision>
     <geometry>
        <box size="0.4 0.03 0.08"/>
      </geometry>
      <origin xyz="0.0 0.0 0.05" />
   </collision>
  </link>

  <joint name="chassis_to_left_pince" type="fixed">
    <parent link="chassis"/>
    <child link="left_pince"/>
    <axis xyz="0 1 0"/>
    <origin xyz="0.4 0.12 0.005" rpy="0 0.0 0.6"/>
  </joint>

  <link name="right_pince">
    <inertial>
     <origin xyz="0 0 0.0" rpy="0 0 0"/>
     <mass value="1"/>
     <inertia ixx="0.0039"  ixy="0"  ixz="0" iyy="0.0034" iyz="0" izz="0.00057" />
   </inertial>
    <visual>
      <geometry>
        <box size="0.4 0.03 0.08"/>
      </geometry>
      <origin xyz="0.0 0.0 0.05" />
    </visual>
    <collision>
     <geometry>
        <box size="0.4 0.03 0.08"/>
      </geometry>
      <origin xyz="0.0 0.0 0.05" />
   </collision>
  </link>

  <joint name="chassis_to_right_pince" type="fixed">
    <parent link="chassis"/>
    <child link="right_pince"/>
    <axis xyz="0 1 0"/>
    <origin xyz="0.4 -0.12 0.005" rpy="0 0.0 -0.6"/>
  </joint>

  <!-- Base Link 
  
  <link name="pince">
    <visual>
        <origin xyz="0 0 0" rpy="0 0 0"/>
        <geometry>
          <mesh filename="package://robot_tennis/meshs/pince2.dae"/>
        </geometry>
    </visual>

    <collision>
        <origin xyz="0 0 0" rpy="0 0 0"/>
        <geometry>
          <mesh filename="package://robot_tennis/meshs/pince2.dae"/>
        </geometry>
    </collision>

    <inertial>
        <origin xyz="0 0 1" rpy="0 0 0"/>
        <mass value="1"/>
        <inertia
            ixx="1.0" ixy="0.0" ixz="0.0"
            iyy="1.0" iyz="0.0"
            izz="1.0"/>
    </inertial>
  </link>

  <joint name="chassis_to_pince" type="fixed">
    <parent link="chassis"/>
    <child link="pince"/>
    <axis xyz="0 0 0"/>
    <origin xyz="1 0 0" rpy="0 0 0"/>
  </joint>-->

  <gazebo>
    <plugin name="diff_drive" filename="libgazebo_ros_diff_drive.so">

      <!-- roues-->
      <left_joint>chassis_to_left_wheel</left_joint>
      <right_joint>chassis_to_right_wheel</right_joint>
      
      <!-- Separation-->
      <wheel_separation>0.36</wheel_separation>
      <wheel_diameter>0.1</wheel_diameter>
      <odometry_frame>odom</odometry_frame>

      <!-- limites  -->
      <max_wheel_torque>20</max_wheel_torque>
      <max_acceleration>1.0</max_acceleration>

      <!-- output -->
      <publish_odom>true</publish_odom>
      <publish_odom_tf>true</publish_odom_tf>
      <publish_wheel_tf>true</publish_wheel_tf>
      <robot_base_frame>chassis</robot_base_frame>

    </plugin>
  </gazebo>


</robot>